<?xml version="1.0" ?>
<robot name="leaderarm" xmlns:xacro="http://www.ros.org/wiki/xacro">

<xacro:include filename="$(find leaderarm_description)/urdf/materials.xacro" />
<xacro:include filename="$(find leaderarm_description)/urdf/leaderarm.trans" />
<xacro:include filename="$(find leaderarm_description)/urdf/leaderarm.gazebo" />
<link name="leader_base_link">
  <inertial>
    <origin xyz="-0.065404 -1e-6 -0.032733" rpy="0 0 0"/>
    <mass value="0.376"/>
    <inertia ixx="0.000629062" iyy="0.001478624" izz="0.001603261" ixy="0.00000003" iyz="0.0" ixz="0.000062369"/>
  </inertial>
  <visual>
    <origin xyz="0 0 0" rpy="0 0 0"/>
    <geometry>
      <mesh filename="file://$(find leaderarm_description)/meshes/base_link.stl" scale="0.001 0.001 0.001"/>
    </geometry>
    <material name="silver"/>
  </visual>
  <collision>
    <origin xyz="0 0 0" rpy="0 0 0"/>
    <geometry>
      <mesh filename="file://$(find leaderarm_description)/meshes/base_link.stl" scale="0.001 0.001 0.001"/>
    </geometry>
  </collision>
</link>

<link name="link_1_leader_1">
  <inertial>
    <origin xyz="-3e-6 -0.00233 0.04133" rpy="0 0 0"/>
    <mass value="0.17"/>
    <inertia ixx="0.000098604" iyy="0.000076082" izz="0.000052417" ixy="-0.000000002" iyz="0.000005468" ixz="0.000000002"/>
  </inertial>
  <visual>
    <origin xyz="0.0145 -0.0145 -0.062" rpy="0 0 0"/>
    <geometry>
      <mesh filename="file://$(find leaderarm_description)/meshes/link_1_leader_1.stl" scale="0.001 0.001 0.001"/>
    </geometry>
    <material name="silver"/>
  </visual>
  <collision>
    <origin xyz="0.0145 -0.0145 -0.062" rpy="0 0 0"/>
    <geometry>
      <mesh filename="file://$(find leaderarm_description)/meshes/link_1_leader_1.stl" scale="0.001 0.001 0.001"/>
    </geometry>
  </collision>
</link>

<link name="link_2_leader_1">
  <inertial>
    <origin xyz="0.006170139685252395 -0.02601295404428107 0.22578322371838686" rpy="0 0 0"/>
    <mass value="0.243"/>
    <inertia ixx="0.000132033" iyy="0.001728174" izz="0.001780092" ixy="-0.000022274" iyz="-0.00000197" ixz="0.000053989"/>
  </inertial>
  <visual>
    <origin xyz="0.0145 -0.0405 -0.1187" rpy="0 0 0"/>
    <geometry>
      <mesh filename="file://$(find leaderarm_description)/meshes/link_2_leader_1.stl" scale="0.001 0.001 0.001"/>
    </geometry>
    <material name="silver"/>
  </visual>
  <collision>
    <origin xyz="0.0145 -0.0405 -0.1187" rpy="0 0 0"/>
    <geometry>
      <mesh filename="file://$(find leaderarm_description)/meshes/link_2_leader_1.stl" scale="0.001 0.001 0.001"/>
    </geometry>
  </collision>
</link>

<link name="link_3_leader_1">
  <inertial>
    <origin xyz="-0.022649618224804397 -0.02632781126242719 0.20370279316133927" rpy="0 0 0"/>
    <mass value="0.18"/>
    <inertia ixx="0.000088026" iyy="0.001017084" izz="0.001030333" ixy="0.000000917" iyz="0.000000019" ixz="-0.000033228"/>
  </inertial>
  <visual>
    <origin xyz="0.014504 -0.04049 -0.4187" rpy="0 0 0"/>
    <geometry>
      <mesh filename="file://$(find leaderarm_description)/meshes/link_3_leader_1.stl" scale="0.001 0.001 0.001"/>
    </geometry>
    <material name="silver"/>
  </visual>
  <collision>
    <origin xyz="0.014504 -0.04049 -0.4187" rpy="0 0 0"/>
    <geometry>
      <mesh filename="file://$(find leaderarm_description)/meshes/link_3_leader_1.stl" scale="0.001 0.001 0.001"/>
    </geometry>
  </collision>
</link>

<link name="link_4_leader_1">
  <inertial>
    <origin xyz="-4.428783816068371e-08 4.482316147522841e-05 0.0345218801269237" rpy="0 0 0"/>
    <mass value="0.137"/>
    <inertia ixx="0.00003736" iyy="0.000056561" izz="0.000069854" ixy="0.000002817" iyz="0.0" ixz="0.0"/>
  </inertial>
  <visual>
    <origin xyz="0.053506 -0.01407 -0.6952" rpy="0 0 0"/>
    <geometry>
      <mesh filename="file://$(find leaderarm_description)/meshes/link_4_leader_1.stl" scale="0.001 0.001 0.001"/>
    </geometry>
    <material name="silver"/>
  </visual>
  <collision>
    <origin xyz="0.053506 -0.01407 -0.6952" rpy="0 0 0"/>
    <geometry>
      <mesh filename="file://$(find leaderarm_description)/meshes/link_4_leader_1.stl" scale="0.001 0.001 0.001"/>
    </geometry>
  </collision>
</link>

<link name="link_5_leader_1">
  <inertial>
    <origin xyz="0.013413342124703492 -0.023509999952198074 0.044037664688921896" rpy="0 0 0"/>
    <mass value="0.136"/>
    <inertia ixx="0.00005204" iyy="0.000064468" izz="0.000044163" ixy="0.0" iyz="0.0" ixz="0.000002644"/>
  </inertial>
  <visual>
    <origin xyz="0.053506 -0.03767 -0.7485" rpy="0 0 0"/>
    <geometry>
      <mesh filename="file://$(find leaderarm_description)/meshes/link_5_leader_1.stl" scale="0.001 0.001 0.001"/>
    </geometry>
    <material name="silver"/>
  </visual>
  <collision>
    <origin xyz="0.053506 -0.03767 -0.7485" rpy="0 0 0"/>
    <geometry>
      <mesh filename="file://$(find leaderarm_description)/meshes/link_5_leader_1.stl" scale="0.001 0.001 0.001"/>
    </geometry>
  </collision>
</link>

<link name="gripper_leader_1">
  <inertial>
    <origin xyz="0.023147156750400244 -0.00016595901113067128 0.0260309860403779" rpy="0 0 0"/>
    <mass value="0.111"/>
    <inertia ixx="0.000143565" iyy="0.000155061" izz="0.00004208" ixy="0.000003559" iyz="0.000003474" ixz="-0.000021804"/>
  </inertial>
  <visual>
    <origin xyz="0.053507 -0.01416 -0.819" rpy="0 0 0"/>
    <geometry>
      <mesh filename="file://$(find leaderarm_description)/meshes/gripper_leader_1.stl" scale="0.001 0.001 0.001"/>
    </geometry>
    <material name="silver"/>
  </visual>
  <collision>
    <origin xyz="0.053507 -0.01416 -0.819" rpy="0 0 0"/>
    <geometry>
      <mesh filename="file://$(find leaderarm_description)/meshes/gripper_leader_1.stl" scale="0.001 0.001 0.001"/>
    </geometry>
  </collision>
</link>

<link name="trigger_leader_1">
  <inertial>
    <origin xyz="-7.730948616696542e-08 -0.0019999999999198263 0.027783233717970868" rpy="0 0 0"/>
    <mass value="0.003"/>
    <inertia ixx="0.00000153" iyy="0.000001901" izz="0.000000381" ixy="0.0" iyz="-0.0" ixz="0.000000379"/>
  </inertial>
  <visual>
    <origin xyz="0.053508 0.00659 -0.8646" rpy="0 0 0"/>
    <geometry>
      <mesh filename="file://$(find leaderarm_description)/meshes/trigger_leader_1.stl" scale="0.001 0.001 0.001"/>
    </geometry>
    <material name="silver"/>
  </visual>
  <collision>
    <origin xyz="0.053508 0.00659 -0.8646" rpy="0 0 0"/>
    <geometry>
      <mesh filename="file://$(find leaderarm_description)/meshes/trigger_leader_1.stl" scale="0.001 0.001 0.001"/>
    </geometry>
  </collision>
</link>

<joint name="leader_rotation1" type="revolute">
  <origin xyz="-0.0145 0.0145 0.062" rpy="0 0 0"/>
  <parent link="leader_base_link"/>
  <child link="link_1_leader_1"/>
  <axis xyz="-0.0 0.0 1.0"/>
  <limit upper="1.570796" lower="-1.570796" effort="100" velocity="100"/>
</joint>

<joint name="leader_rotation2" type="revolute">
  <origin xyz="0.0 0.026 0.0567" rpy="0 0 0"/>
  <parent link="link_1_leader_1"/>
  <child link="link_2_leader_1"/>
  <axis xyz="0.0 1.0 -0.0"/>
  <limit upper="1.570796" lower="-1.570796" effort="100" velocity="100"/>
</joint>

<joint name="leader_rotation3" type="revolute">
  <origin xyz="-4e-06 -1e-05 0.3" rpy="0 0 0"/>
  <parent link="link_2_leader_1"/>
  <child link="link_3_leader_1"/>
  <axis xyz="-0.0 1.0 -0.0"/>
  <limit upper="3.141593" lower="0.0" effort="100" velocity="100"/>
</joint>

<joint name="leader_rotation4" type="revolute">
  <origin xyz="-0.039002 -0.02642 0.2765" rpy="0 0 0"/>
  <parent link="link_3_leader_1"/>
  <child link="link_4_leader_1"/>
  <axis xyz="-1.2e-05 0.0 1.0"/>
  <limit upper="1.570796" lower="-1.570796" effort="100" velocity="100"/>
</joint>

<joint name="leader_rotation5" type="revolute">
  <origin xyz="0.0 0.0236 0.0533" rpy="0 0 0"/>
  <parent link="link_4_leader_1"/>
  <child link="link_5_leader_1"/>
  <axis xyz="0.0 1.0 -0.0"/>
  <limit upper="1.570796" lower="-1.570796" effort="100" velocity="100"/>
</joint>

<joint name="leader_rotation6" type="revolute">
  <origin xyz="-1e-06 -0.02351 0.0705" rpy="0 0 0"/>
  <parent link="link_5_leader_1"/>
  <child link="gripper_leader_1"/>
  <axis xyz="-1.2e-05 0.0 1.0"/>
  <limit upper="1.570796" lower="-1.570796" effort="100" velocity="100"/>
</joint>

<joint name="leader_rotation7" type="revolute">
  <origin xyz="-1e-06 -0.02075 0.0456" rpy="0 0 0"/>
  <parent link="gripper_leader_1"/>
  <child link="trigger_leader_1"/>
  <axis xyz="0.0 -1.0 0.0"/>
  <limit upper="0.0" lower="-1.570796" effort="100" velocity="100"/>
</joint>

<ros2_control name="LeaderHardware" type="system">
    <hardware>
      <plugin>dynamixel_hardware_interface/DynamixelHardware</plugin>
      <param name="port_name">/dev/USBleader</param>
      <param name="baud_rate">1000000</param>
      <param name="dynamixel_model_folder">/param/dxl_model/</param>
      <param name="number_of_joints">7</param> 
      <param name="number_of_transmissions">7</param>
      <param name="loop_rate">100</param>
      <param name="use_fast_read">false</param>            <param name="use_indirect_address">true</param>
      <param name="error_timeout_ms">4000</param>
      <param name="disable_torque_at_init">false</param>
      <param name="torque_enable">true</param>
    </hardware>
    
    <joint name="leader_rotation1"><param name="id">1</param><param name="torque_enable">true</param><command_interface name="position"/><command_interface name="effort"/><state_interface name="position"/><state_interface name="velocity"/><state_interface name="effort"/></joint>
    <joint name="leader_rotation2"><param name="id">2</param><param name="torque_enable">true</param><command_interface name="position"/><command_interface name="effort"/><state_interface name="position"/><state_interface name="velocity"/><state_interface name="effort"/></joint>
    <joint name="leader_rotation3"><param name="id">3</param><param name="torque_enable">true</param><command_interface name="position"/><command_interface name="effort"/><state_interface name="position"/><state_interface name="velocity"/><state_interface name="effort"/></joint>
    <joint name="leader_rotation4"><param name="id">4</param><param name="torque_enable">true</param><command_interface name="position"/><command_interface name="effort"/><state_interface name="position"/><state_interface name="velocity"/><state_interface name="effort"/></joint>
    <joint name="leader_rotation5"><param name="id">5</param><param name="torque_enable">true</param><command_interface name="position"/><command_interface name="effort"/><state_interface name="position"/><state_interface name="velocity"/><state_interface name="effort"/></joint>
    <joint name="leader_rotation6"><param name="id">6</param><param name="torque_enable">true</param><command_interface name="position"/><command_interface name="effort"/><state_interface name="position"/><state_interface name="velocity"/><state_interface name="effort"/></joint>
    <joint name="leader_rotation7"><param name="id">7</param><param name="torque_enable">true</param><command_interface name="position"/><command_interface name="effort"/><state_interface name="position"/><state_interface name="velocity"/><state_interface name="effort"/></joint>

    <gpio name="dxl1">
      <param name="type">dxl</param><param name="ID">1</param>
      <param name="Operating Mode">0</param>
      <param name="Return Delay Time">10</param>
      <param name="Torque Enable">1</param>
      <command_interface name="Goal Current"/><state_interface name="Present Position"/>
    </gpio>
    <gpio name="dxl2">
      <param name="type">dxl</param><param name="ID">2</param>
      <param name="Operating Mode">0</param>
      <param name="Return Delay Time">10</param>
      <param name="Torque Enable">1</param>
      <command_interface name="Goal Current"/><state_interface name="Present Position"/>
    </gpio>
    <gpio name="dxl3">
      <param name="type">dxl</param><param name="ID">3</param>
      <param name="Operating Mode">0</param>
      <param name="Return Delay Time">10</param>
      <param name="Torque Enable">1</param>
      <command_interface name="Goal Current"/><state_interface name="Present Position"/>
    </gpio>
    <gpio name="dxl4">
      <param name="type">dxl</param><param name="ID">4</param>
      <param name="Operating Mode">0</param>
      <param name="Return Delay Time">10</param>
      <param name="Torque Enable">1</param>
      <command_interface name="Goal Current"/><state_interface name="Present Position"/>
    </gpio>
    <gpio name="dxl5">
      <param name="type">dxl</param><param name="ID">5</param>
      <param name="Operating Mode">0</param>
      <param name="Return Delay Time">10</param>
      <param name="Torque Enable">1</param>
      <command_interface name="Goal Current"/><state_interface name="Present Position"/>
    </gpio>
    <gpio name="dxl6">
      <param name="type">dxl</param><param name="ID">6</param>
      <param name="Operating Mode">0</param>
      <param name="Return Delay Time">10</param>
      <param name="Torque Enable">1</param>
      <command_interface name="Goal Current"/><state_interface name="Present Position"/>
    </gpio>
    <gpio name="dxl7">
      <param name="type">dxl</param><param name="ID">7</param>
      <param name="Operating Mode">16</param>
      <param name="Return Delay Time">10</param>
      <param name="Torque Enable">1</param>
      <command_interface name="Goal PWM"/><state_interface name="Present Position"/>
    </gpio>
  </ros2_control>

</robot>
